Workbook

Sheet DATA_KPI
A1: month | B1: month_name | C1: net_sales_inr | D1: gross_profit_inr | E1: gp_margin_pct | F1: sales_target_inr | G1: target_achievement_pct | H1: total_opex_inr | I1: opex_budget_inr | J1: opex_variance_pct | K1: grn_units | L1: issue_units | M1: damage_units | N1: dispatch_trips | O1: on_time_deliveries | P1: otd_pct | Q1: invoices_raised | R1: active_customers | S1: active_skus
A2: 1 | B2: Jan-2024 | C2: 4218747 | D2: 1435282 | E2: 34 | F2: 4534552 | G2: 93 | H2: 1511305 | I2: 1438800 | J2: 5 | K2: 214939 | L2: 207847 | M2: 1685 | N2: 109 | O2: 92 | P2: 84.4 | Q2: 816 | R2: 35 | S2: 30
A3: 2 | B3: Feb-2024 | C3: 3961742 | D3: 1346950 | E3: 34 | F3: 4328436 | G3: 91.5 | H3: 1384117 | I3: 1373400 | J3: 0.8 | K3: 208754 | L3: 200965 | M3: 1407 | N3: 110 | O3: 94 | P3: 85.5 | Q3: 778 | R3: 35 | S3: 30
A4: 3 | B4: Mar-2024 | C4: 4348825 | D4: 1477494 | E4: 34 | F4: 4740668 | G4: 91.7 | H4: 1523159 | I4: 1504200 | J4: 1.3 | K4: 225184 | L4: 219143 | M4: 1678 | N4: 110 | O4: 92 | P4: 83.6 | Q4: 762 | R4: 35 | S4: 30
A5: 4 | B5: Apr-2024 | C5: 4984264 | D5: 1698341 | E5: 34.1 | F5: 5410545 | G5: 92.1 | H5: 1756110 | I5: 1716750 | J5: 2.3 | K5: 257000 | L5: 248721 | M5: 2026 | N5: 123 | O5: 107 | P5: 87 | Q5: 778 | R5: 35 | S5: 30
A6: 5 | B6: May-2024 | C6: 5091131 | D6: 1734436 | E6: 34.1 | F6: 5668190 | G6: 89.8 | H6: 1820473 | I6: 1798500 | J6: 1.2 | K6: 269108 | L6: 259756 | M6: 1943 | N6: 126 | O6: 109 | P6: 86.5 | Q6: 779 | R6: 35 | S6: 30
A7: 6 | B7: Jun-2024 | C7: 5151644 | D7: 1755466 | E7: 34.1 | F7: 5565132 | G7: 92.6 | H7: 1789992 | I7: 1765800 | J7: 1.4 | K7: 264598 | L7: 253969 | M7: 1881 | N7: 116 | O7: 106 | P7: 91.4 | Q7: 792 | R7: 35 | S7: 30
A8: 7 | B8: Jul-2024 | C8: 4722487 | D8: 1610196 | E8: 34.1 | F8: 4895255 | G8: 96.5 | H8: 1558429 | I8: 1553250 | J8: 0.3 | K8: 233892 | L8: 225555 | M8: 1668 | N8: 114 | O8: 100 | P8: 87.7 | Q8: 830 | R8: 35 | S8: 30
A9: 8 | B9: Aug-2024 | C9: 4709355 | D9: 1611894 | E9: 34.2 | F9: 4998313 | G9: 94.2 | H9: 1639159 | I9: 1585950 | J9: 3.4 | K9: 238114 | L9: 231442 | M9: 1545 | N9: 111 | O9: 94 | P9: 84.7 | Q9: 765 | R9: 35 | S9: 30
A10: 9 | B10: Sep-2024 | C10: 4823787 | D10: 1636204 | E10: 33.9 | F10: 5152900 | G10: 93.6 | H10: 1584320 | I10: 1635000 | J10: -3.1 | K10: 245240 | L10: 236764 | M10: 1805 | N10: 123 | O10: 99 | P10: 80.5 | Q10: 793 | R10: 35 | S10: 30
A11: 10 | B11: Oct-2024 | C11: 5731787 | D11: 1954672 | E11: 34.1 | F11: 6080422 | G11: 94.3 | H11: 1921428 | I11: 1929300 | J11: -0.4 | K11: 288651 | L11: 276458 | M11: 2192 | N11: 107 | O11: 91 | P11: 85 | Q11: 791 | R11: 35 | S11: 30
A12: 11 | B12: Nov-2024 | C12: 5872524 | D12: 1998563 | E12: 34 | F12: 6286538 | G12: 93.4 | H12: 2064848 | I12: 1994700 | J12: 3.5 | K12: 299758 | L12: 286876 | M12: 2276 | N12: 118 | O12: 101 | P12: 85.6 | Q12: 799 | R12: 35 | S12: 30
A13: 12 | B13: Dec-2024 | C13: 4931100 | D13: 1682741 | E13: 34.1 | F13: 5410545 | G13: 91.1 | H13: 1770972 | I13: 1716750 | J13: 3.2 | K13: 256200 | L13: 248112 | M13: 1853 | N13: 109 | O13: 89 | P13: 81.7 | Q13: 737 | R13: 35 | S13: 30

Sheet 📊 Sales MIS
A1: SHREENATH AGRO & FMCG DISTRIBUTORS PVT. LTD.
A2: Monthly Sales MIS Report — FY 2024 | Nagpur, Maharashtra
B4: 📦 TOTAL NET SALES | C4: 🎯 TOTAL TARGET | D4: 📈 ACHIEVEMENT % | E4: 💰 GROSS PROFIT | F4: 📊 GP MARGIN % | G4: ⚙️ TOTAL OPEX | H4: 📋 OPEX BUDGET
B5: =SUM(DATA_KPI!C2:C13) -> 58547393 | C5: =SUM(DATA_KPI!F2:F13) -> 63071496 | D5: =E20 -> 92.827024 | E5: =SUM(DATA_KPI!D2:D13) -> 19942239 | F5: =G20 -> 34.061703 | G5: =SUM(DATA_KPI!H2:H13) -> 20324312 | H5: =SUM(DATA_KPI!I2:I13) -> 20012400
A7: # | B7: Month | C7: Actual Sales (₹) | D7: Target Sales (₹) | E7: Achievement % | F7: Gross Profit (₹) | G7: GP Margin % | H7: Total OpEx (₹)
A8: 1 | B8: =DATA_KPI!B2 -> Jan-2024 | C8: =DATA_KPI!C2 -> 4218747 | D8: =DATA_KPI!F2 -> 4534552 | E8: =IFERROR(C8/D8,0) -> 0.93035585 | F8: =DATA_KPI!D2 -> 1435282 | G8: =IFERROR(F8/C8*100,0) -> 34.021523 | H8: =DATA_KPI!H2 -> 1511305
A9: 2 | B9: =DATA_KPI!B3 -> Feb-2024 | C9: =DATA_KPI!C3 -> 3961742 | D9: =DATA_KPI!F3 -> 4328436 | E9: =IFERROR(C9/D9,0) -> 0.91528256 | F9: =DATA_KPI!D3 -> 1346950 | G9: =IFERROR(F9/C9*100,0) -> 33.998933 | H9: =DATA_KPI!H3 -> 1384117
A10: 3 | B10: =DATA_KPI!B4 -> Mar-2024 | C10: =DATA_KPI!C4 -> 4348825 | D10: =DATA_KPI!F4 -> 4740668 | E10: =IFERROR(C10/D10,0) -> 0.91734435 | F10: =DATA_KPI!D4 -> 1477494 | G10: =IFERROR(F10/C10*100,0) -> 33.974556 | H10: =DATA_KPI!H4 -> 1523159
A11: 4 | B11: =DATA_KPI!B5 -> Apr-2024 | C11: =DATA_KPI!C5 -> 4984264 | D11: =DATA_KPI!F5 -> 5410545 | E11: =IFERROR(C11/D11,0) -> 0.92121293 | F11: =DATA_KPI!D5 -> 1698341 | G11: =IFERROR(F11/C11*100,0) -> 34.074058 | H11: =DATA_KPI!H5 -> 1756110
A12: 5 | B12: =DATA_KPI!B6 -> May-2024 | C12: =DATA_KPI!C6 -> 5091131 | D12: =DATA_KPI!F6 -> 5668190 | E12: =IFERROR(C12/D12,0) -> 0.89819343 | F12: =DATA_KPI!D6 -> 1734436 | G12: =IFERROR(F12/C12*100,0) -> 34.067794 | H12: =DATA_KPI!H6 -> 1820473
A13: 6 | B13: =DATA_KPI!B7 -> Jun-2024 | C13: =DATA_KPI!C7 -> 5151644 | D13: =DATA_KPI!F7 -> 5565132 | E13: =IFERROR(C13/D13,0) -> 0.92570023 | F13: =DATA_KPI!D7 -> 1755466 | G13: =IFERROR(F13/C13*100,0) -> 34.075841 | H13: =DATA_KPI!H7 -> 1789992
A14: 7 | B14: =DATA_KPI!B8 -> Jul-2024 | C14: =DATA_KPI!C8 -> 4722487 | D14: =DATA_KPI!F8 -> 4895255 | E14: =IFERROR(C14/D14,0) -> 0.96470705 | F14: =DATA_KPI!D8 -> 1610196 | G14: =IFERROR(F14/C14*100,0) -> 34.096356 | H14: =DATA_KPI!H8 -> 1558429
A15: 8 | B15: =DATA_KPI!B9 -> Aug-2024 | C15: =DATA_KPI!C9 -> 4709355 | D15: =DATA_KPI!F9 -> 4998313 | E15: =IFERROR(C15/D15,0) -> 0.94218889 | F15: =DATA_KPI!D9 -> 1611894 | G15: =IFERROR(F15/C15*100,0) -> 34.22749 | H15: =DATA_KPI!H9 -> 1639159
A16: 9 | B16: =DATA_KPI!B10 -> Sep-2024 | C16: =DATA_KPI!C10 -> 4823787 | D16: =DATA_KPI!F10 -> 5152900 | E16: =IFERROR(C16/D16,0) -> 0.93613053 | F16: =DATA_KPI!D10 -> 1636204 | G16: =IFERROR(F16/C16*100,0) -> 33.919491 | H16: =DATA_KPI!H10 -> 1584320
A17: 10 | B17: =DATA_KPI!B11 -> Oct-2024 | C17: =DATA_KPI!C11 -> 5731787 | D17: =DATA_KPI!F11 -> 6080422 | E17: =IFERROR(C17/D17,0) -> 0.9426627 | F17: =DATA_KPI!D11 -> 1954672 | G17: =IFERROR(F17/C17*100,0) -> 34.102314 | H17: =DATA_KPI!H11 -> 1921428
A18: 11 | B18: =DATA_KPI!B12 -> Nov-2024 | C18: =DATA_KPI!C12 -> 5872524 | D18: =DATA_KPI!F12 -> 6286538 | E18: =IFERROR(C18/D18,0) -> 0.93414277 | F18: =DATA_KPI!D12 -> 1998563 | G18: =IFERROR(F18/C18*100,0) -> 34.032436 | H18: =DATA_KPI!H12 -> 2064848
A19: 12 | B19: =DATA_KPI!B13 -> Dec-2024 | C19: =DATA_KPI!C13 -> 4931100 | D19: =DATA_KPI!F13 -> 5410545 | E19: =IFERROR(C19/D19,0) -> 0.91138693 | F19: =DATA_KPI!D13 -> 1682741 | G19: =IFERROR(F19/C19*100,0) -> 34.125063 | H19: =DATA_KPI!H13 -> 1770972
B20: GRAND TOTAL | C20: =SUM(C8:C19) -> 58547393 | D20: =SUM(D8:D19) -> 63071496 | E20: =IFERROR(C20/D20*100,0) -> 92.827024 | F20: =SUM(F8:F19) -> 19942239 | G20: =IFERROR(F20/C20*100,0) -> 34.061703 | H20: =SUM(H8:H19) -> 20324312

Sheet 📦 Inventory Report
A1: INVENTORY & STOCK ANALYSIS — FY 2024
A2: Monthly Inventory KPIs | Shreenath Agro & FMCG Distributors
B4: 📥 TOTAL GRN UNITS | C4: 📤 TOTAL ISSUED UNITS | D4: ⚠️ TOTAL DAMAGE UNITS | E4: 🚛 DISPATCH TRIPS | F4: ✅ ON-TIME DELIVERS | G4: 📊 AVG OTD % | H4: 📋 DAMAGE RATE %
B5: =SUM(DATA_KPI!J2:J13) -> 18.9 | C5: =SUM(DATA_KPI!K2:K13) -> 3001438 | D5: =SUM(DATA_KPI!L2:L13) -> 2895608 | E5: =SUM(DATA_KPI!M2:M13) -> 21959 | F5: =SUM(DATA_KPI!N2:N13) -> 1376 | G5: =IFERROR(AVERAGE(DATA_KPI!O2:O13),0) -> 97.833333 | H5: =IFERROR(D5/B5*100,0) -> 15320677
A7: # | B7: Month | C7: GRN Units | D7: Issued Units | E7: Damage Units | F7: Net Movement | G7: Damage Rate % | H7: OTD %
A8: 1 | B8: =DATA_KPI!B2 -> Jan-2024 | C8: =DATA_KPI!J2 -> 5 | D8: =DATA_KPI!K2 -> 214939 | E8: =DATA_KPI!L2 -> 207847 | F8: =C8-D8-E8 -> -422781 | G8: =IFERROR(E8/C8*100,0) -> 4156940 | H8: =DATA_KPI!O2 -> 92
A9: 2 | B9: =DATA_KPI!B3 -> Feb-2024 | C9: =DATA_KPI!J3 -> 0.8 | D9: =DATA_KPI!K3 -> 208754 | E9: =DATA_KPI!L3 -> 200965 | F9: =C9-D9-E9 -> -409718.2 | G9: =IFERROR(E9/C9*100,0) -> 25120625 | H9: =DATA_KPI!O3 -> 94
A10: 3 | B10: =DATA_KPI!B4 -> Mar-2024 | C10: =DATA_KPI!J4 -> 1.3 | D10: =DATA_KPI!K4 -> 225184 | E10: =DATA_KPI!L4 -> 219143 | F10: =C10-D10-E10 -> -444325.7 | G10: =IFERROR(E10/C10*100,0) -> 16857154 | H10: =DATA_KPI!O4 -> 92
A11: 4 | B11: =DATA_KPI!B5 -> Apr-2024 | C11: =DATA_KPI!J5 -> 2.3 | D11: =DATA_KPI!K5 -> 257000 | E11: =DATA_KPI!L5 -> 248721 | F11: =C11-D11-E11 -> -505718.7 | G11: =IFERROR(E11/C11*100,0) -> 10813957 | H11: =DATA_KPI!O5 -> 107
A12: 5 | B12: =DATA_KPI!B6 -> May-2024 | C12: =DATA_KPI!J6 -> 1.2 | D12: =DATA_KPI!K6 -> 269108 | E12: =DATA_KPI!L6 -> 259756 | F12: =C12-D12-E12 -> -528862.8 | G12: =IFERROR(E12/C12*100,0) -> 21646333 | H12: =DATA_KPI!O6 -> 109
A13: 6 | B13: =DATA_KPI!B7 -> Jun-2024 | C13: =DATA_KPI!J7 -> 1.4 | D13: =DATA_KPI!K7 -> 264598 | E13: =DATA_KPI!L7 -> 253969 | F13: =C13-D13-E13 -> -518565.6 | G13: =IFERROR(E13/C13*100,0) -> 18140643 | H13: =DATA_KPI!O7 -> 106
A14: 7 | B14: =DATA_KPI!B8 -> Jul-2024 | C14: =DATA_KPI!J8 -> 0.3 | D14: =DATA_KPI!K8 -> 233892 | E14: =DATA_KPI!L8 -> 225555 | F14: =C14-D14-E14 -> -459446.7 | G14: =IFERROR(E14/C14*100,0) -> 75185000 | H14: =DATA_KPI!O8 -> 100
A15: 8 | B15: =DATA_KPI!B9 -> Aug-2024 | C15: =DATA_KPI!J9 -> 3.4 | D15: =DATA_KPI!K9 -> 238114 | E15: =DATA_KPI!L9 -> 231442 | F15: =C15-D15-E15 -> -469552.6 | G15: =IFERROR(E15/C15*100,0) -> 6807117.6 | H15: =DATA_KPI!O9 -> 94
A16: 9 | B16: =DATA_KPI!B10 -> Sep-2024 | C16: =DATA_KPI!J10 -> -3.1 | D16: =DATA_KPI!K10 -> 245240 | E16: =DATA_KPI!L10 -> 236764 | F16: =C16-D16-E16 -> -482007.1 | G16: =IFERROR(E16/C16*100,0) -> -7637548.4 | H16: =DATA_KPI!O10 -> 99
A17: 10 | B17: =DATA_KPI!B11 -> Oct-2024 | C17: =DATA_KPI!J11 -> -0.4 | D17: =DATA_KPI!K11 -> 288651 | E17: =DATA_KPI!L11 -> 276458 | F17: =C17-D17-E17 -> -565109.4 | G17: =IFERROR(E17/C17*100,0) -> -69114500 | H17: =DATA_KPI!O11 -> 91
A18: 11 | B18: =DATA_KPI!B12 -> Nov-2024 | C18: =DATA_KPI!J12 -> 3.5 | D18: =DATA_KPI!K12 -> 299758 | E18: =DATA_KPI!L12 -> 286876 | F18: =C18-D18-E18 -> -586630.5 | G18: =IFERROR(E18/C18*100,0) -> 8196457.1 | H18: =DATA_KPI!O12 -> 101
A19: 12 | B19: =DATA_KPI!B13 -> Dec-2024 | C19: =DATA_KPI!J13 -> 3.2 | D19: =DATA_KPI!K13 -> 256200 | E19: =DATA_KPI!L13 -> 248112 | F19: =C19-D19-E19 -> -504308.8 | G19: =IFERROR(E19/C19*100,0) -> 7753500 | H19: =DATA_KPI!O13 -> 89
B20: FULL YEAR TOTAL | C20: =SUM(C8:C19) -> 18.9 | D20: =SUM(D8:D19) -> 3001438 | E20: =SUM(E8:E19) -> 2895608 | F20: =SUM(F8:F19) -> -5897027.1 | G20: =IFERROR(E20/C20*100,0) -> 15320677 | H20: =IFERROR(AVERAGE(H8:H19),0) -> 97.833333
A22: SKU-WISE PERFORMANCE SUMMARY
A23: # | B23: SKU Name | C23: Category | D23: Brand | E23: Total Units Sold | F23: Total Net Sales (₹) | G23: Total Gross Profit (₹) | H23: GP %
A24: 1 | B24: Aashirvaad Atta 5kg | C24: Staples | D24: ITC | E24: 30452 | F24: 6784641.9 | G24: 2324347.8 | H24: =IFERROR(G24/F24*100,0) -> 34.258961
A25: 2 | B25: Fortune Soyabean Oil 1L | C25: Staples | D25: Adani | E25: 36518 | F25: 4764156.4 | G25: 1631853.6 | H25: =IFERROR(G25/F25*100,0) -> 34.252729
A26: 3 | B26: Surf Excel 1kg | C26: Detergent | D26: HUL | E26: 20994 | F26: 4351124.3 | G26: 1491682.6 | H26: =IFERROR(G26/F26*100,0) -> 34.282692
A27: 4 | B27: Ariel Matic 1kg | C27: Detergent | D27: P&G | E27: 18103 | F27: 3930147.9 | G27: 1357210 | H27: =IFERROR(G27/F27*100,0) -> 34.533306
A28: 5 | B28: Tata Tea Premium 250g | C28: Tea/Coffee | D28: Tata | E28: 23811 | F28: 3807808.1 | G28: 1319403.9 | H28: =IFERROR(G28/F28*100,0) -> 34.649957
A29: 6 | B29: Bru Coffee 200g | C29: Tea/Coffee | D29: HUL | E29: 10615 | F29: 2977306.7 | G29: 1020593.6 | H29: =IFERROR(G29/F29*100,0) -> 34.279088
A30: 7 | B30: Haldiram's Mixture 1kg | C30: Namkeen | D30: Haldiram's | E30: 13722 | F30: 2592835 | G30: 890825.85 | H30: =IFERROR(G30/F30*100,0) -> 34.357213
A31: 8 | B31: Maggi Masala 70g x 6pk | C31: Noodles | D31: Nestle | E31: 33174 | F31: 2567136.8 | G31: 884611.2 | H31: =IFERROR(G31/F31*100,0) -> 34.45906
A32: 9 | B32: Head & Shoulders 180ml | C32: Hair Care | D32: P&G | E32: 12952 | F32: 2193993.4 | G32: 753038.5 | H32: =IFERROR(G32/F32*100,0) -> 34.322734
A33: 10 | B33: Colgate Total 150g | C33: Oral Care | D33: Colgate | E33: 22565 | F33: 2150704.7 | G33: 747378.25 | H33: =IFERROR(G33/F33*100,0) -> 34.75039
A34: 11 | B34: Haldiram's Aloo Bhujia 400g | C34: Namkeen | D34: Haldiram's | E34: 24048 | F34: 1971101.6 | G34: 684224.45 | H34: =IFERROR(G34/F34*100,0) -> 34.712795
A35: 12 | B35: Lifebuoy Soap 125g | C35: Soap | D35: HUL | E35: 40438 | F35: 1952593.6 | G35: 692535.5 | H35: =IFERROR(G35/F35*100,0) -> 35.467468
... A53: 30 | B53: Haldiram's Paneer Tikka 60g | C53: Snacks | D53: Haldiram's | E53: 8986 | F53: 174274.72 | G53: 60125.8 | H53: =IFERROR(G53/F53*100,0) -> 34.500586

Sheet 💰 Cost Variance
A1: COST BUDGET vs ACTUAL — FY 2024
A2: Monthly OpEx Variance Analysis | Shreenath Agro & FMCG Distributors
B4: 💰 TOTAL ACTUAL OPEX | C4: 📋 TOTAL BUDGET | D4: 📊 ANNUAL VARIANCE ₹ | E4: 📈 VARIANCE % | F4: 📦 MONTHS OVER BUDGET | G4: ✅ MONTHS UNDER BUDGET | H4: ⚖️ STATUS
B5: =SUM(DATA_COST!E2:E121) -> 20324312 | C5: =SUM(DATA_COST!D2:D121) -> 20012400 | D5: =SUM(DATA_COST!F2:F121) -> 311912 | E5: =IFERROR((C5-D5)/D5*100,0) -> 6316.0404 | F5: =COUNTIF(DATA_COST!H2:H121,"Over Budget") -> 25 | G5: =COUNTIF(DATA_COST!H2:H121,"Under Budget") -> 13 | H5: =IF(E5>5,"🔴 Over Budget",IF(E5<-5,"🟢 Under Budget","🟡 On Track")) -> 🔴 Over Budget | I5: =IF(E5>5,"🔴 Over Budget",IF(E5<-5,"🟢 Under Budget","🟡 On Track")) -> 🔴 Over Budget
A7: # | B7: Month | C7: Cost Category | D7: Budget (₹) | E7: Actual (₹) | F7: Variance (₹) | G7: Variance % | H7: Flag
A8: 1 | B8: =DATA_COST!B2 -> Jan-2024 | C8: =DATA_COST!C2 -> Salaries & Wages | D8: =DATA_COST!D2 -> 572000 | E8: =DATA_COST!E2 -> 582421 | F8: =E8-D8 -> 10421 | G8: =IFERROR(F8/D8*100,0) -> 1.8218531 | H8: =IF(G8>5,"🔴 Over Budget",IF(G8<-5,"🟢 Under Budget","🟡 On Track")) -> 🟡 On Track
A9: 2 | B9: =DATA_COST!B3 -> Jan-2024 | C9: =DATA_COST!C3 -> Vehicle Fuel & Maintenance | D9: =DATA_COST!D3 -> 246400 | E9: =DATA_COST!E3 -> 281763 | F9: =E9-D9 -> 35363 | G9: =IFERROR(F9/D9*100,0) -> 14.351867 | H9: =IF(G9>5,"🔴 Over Budget",IF(G9<-5,"🟢 Under Budget","🟡 On Track")) -> 🔴 Over Budget
A10: 3 | B10: =DATA_COST!B4 -> Jan-2024 | C10: =DATA_COST!C4 -> Depot Rent & Utilities | D10: =DATA_COST!D4 -> 158400 | E10: =DATA_COST!E4 -> 160378 | F10: =E10-D10 -> 1978 | G10: =IFERROR(F10/D10*100,0) -> 1.2487374 | H10: =IF(G10>5,"🔴 Over Budget",IF(G10<-5,"🟢 Under Budget","🟡 On Track")) -> 🟡 On Track
A11: 4 | B11: =DATA_COST!B5 -> Jan-2024 | C11: =DATA_COST!C5 -> Sales Incentives | D11: =DATA_COST!D5 -> 105600 | E11: =DATA_COST!E5 -> 132760 | F11: =E11-D11 -> 27160 | G11: =IFERROR(F11/D11*100,0) -> 25.719697 | H11: =IF(G11>5,"🔴 Over Budget",IF(G11<-5,"🟢 Under Budget","🟡 On Track")) -> 🔴 Over Budget
A12: 5 | B12: =DATA_COST!B6 -> Jan-2024 | C12: =DATA_COST!C6 -> Packaging & Labelling | D12: =DATA_COST!D6 -> 83600 | E12: =DATA_COST!E6 -> 87488 | F12: =E12-D12 -> 3888 | G12: =IFERROR(F12/D12*100,0) -> 4.6507177 | H12: =IF(G12>5,"🔴 Over Budget",IF(G12<-5,"🟢 Under Budget","🟡 On Track")) -> 🟡 On Track
A13: 6 | B13: =DATA_COST!B7 -> Jan-2024 | C13: =DATA_COST!C7 -> Warehouse Operations | D13: =DATA_COST!D7 -> 96800 | E13: =DATA_COST!E7 -> 90560 | F13: =E13-D13 -> -6240 | G13: =IFERROR(F13/D13*100,0) -> -6.446281 | H13: =IF(G13>5,"🔴 Over Budget",IF(G13<-5,"🟢 Under Budget","🟡 On Track")) -> 🟢 Under Budget
A14: 7 | B14: =DATA_COST!B8 -> Jan-2024 | C14: =DATA_COST!C8 -> Office & Admin | D14: =DATA_COST!D8 -> 48400 | E14: =DATA_COST!E8 -> 50147 | F14: =E14-D14 -> 1747 | G14: =IFERROR(F14/D14*100,0) -> 3.6095041 | H14: =IF(G14>5,"🔴 Over Budget",IF(G14<-5,"🟢 Under Budget","🟡 On Track")) -> 🟡 On Track
A15: 8 | B15: =DATA_COST!B9 -> Jan-2024 | C15: =DATA_COST!C9 -> Communication & IT | D15: =DATA_COST!D9 -> 35200 | E15: =DATA_COST!E9 -> 34471 | F15: =E15-D15 -> -729 | G15: =IFERROR(F15/D15*100,0) -> -2.0710227 | H15: =IF(G15>5,"🔴 Over Budget",IF(G15<-5,"🟢 Under Budget","🟡 On Track")) -> 🟡 On Track
A16: 9 | B16: =DATA_COST!B10 -> Jan-2024 | C16: =DATA_COST!C10 -> Insurance & Compliance | D16: =DATA_COST!D10 -> 66000 | E16: =DATA_COST!E10 -> 66034 | F16: =E16-D16 -> 34 | G16: =IFERROR(F16/D16*100,0) -> 0.051515152 | H16: =IF(G16>5,"🔴 Over Budget",IF(G16<-5,"🟢 Under Budget","🟡 On Track")) -> 🟡 On Track
A17: 10 | B17: =DATA_COST!B11 -> Jan-2024 | C17: =DATA_COST!C11 -> Miscellaneous | D17: =DATA_COST!D11 -> 26400 | E17: =DATA_COST!E11 -> 25283 | F17: =E17-D17 -> -1117 | G17: =IFERROR(F17/D17*100,0) -> -4.2310606 | H17: =IF(G17>5,"🔴 Over Budget",IF(G17<-5,"🟢 Under Budget","🟡 On Track")) -> 🟡 On Track
A18: 11 | B18: =DATA_COST!B12 -> Feb-2024 | C18: =DATA_COST!C12 -> Salaries & Wages | D18: =DATA_COST!D12 -> 546000 | E18: =DATA_COST!E12 -> 539738 | F18: =E18-D18 -> -6262 | G18: =IFERROR(F18/D18*100,0) -> -1.1468864 | H18: =IF(G18>5,"🔴 Over Budget",IF(G18<-5,"🟢 Under Budget","🟡 On Track")) -> 🟡 On Track
A19: 12 | B19: =DATA_COST!B13 -> Feb-2024 | C19: =DATA_COST!C13 -> Vehicle Fuel & Maintenance | D19: =DATA_COST!D13 -> 235200 | E19: =DATA_COST!E13 -> 234981 | F19: =E19-D19 -> -219 | G19: =IFERROR(F19/D19*100,0) -> -0.093112245 | H19: =IF(G19>5,"🔴 Over Budget",IF(G19<-5,"🟢 Under Budget","🟡 On Track")) -> 🟡 On Track
... A127: 120 | B127: =DATA_COST!B121 -> Dec-2024 | C127: =DATA_COST!C121 -> Miscellaneous | D127: =DATA_COST!D121 -> 31500 | E127: =DATA_COST!E121 -> 35490 | F127: =E127-D127 -> 3990 | G127: =IFERROR(F127/D127*100,0) -> 12.666667 | H127: =IF(G127>5,"🔴 Over Budget",IF(G127<-5,"🟢 Under Budget","🟡 On Track")) -> 🔴 Over Budget
B128: GRAND TOTAL | D128: =SUM(D8:D127) -> 20012400 | E128: =SUM(E8:E127) -> 20324312 | F128: =SUM(F8:F127) -> 311912 | G128: =IFERROR(F128/D128*100,0) -> 1.5585937

Sheet DATA_COST
A1: month | B1: month_name | C1: cost_category | D1: budget_inr | E1: actual_inr | F1: variance_inr | G1: variance_pct | H1: flag
A2: 1 | B2: Jan-2024 | C2: Salaries & Wages | D2: 572000 | E2: 582421 | F2: 10421 | G2: 1.8 | H2: On Track
A3: 1 | B3: Jan-2024 | C3: Vehicle Fuel & Maintenance | D3: 246400 | E3: 281763 | F3: 35363 | G3: 14.4 | H3: Over Budget
A4: 1 | B4: Jan-2024 | C4: Depot Rent & Utilities | D4: 158400 | E4: 160378 | F4: 1978 | G4: 1.2 | H4: On Track
A5: 1 | B5: Jan-2024 | C5: Sales Incentives | D5: 105600 | E5: 132760 | F5: 27160 | G5: 25.7 | H5: Over Budget
A6: 1 | B6: Jan-2024 | C6: Packaging & Labelling | D6: 83600 | E6: 87488 | F6: 3888 | G6: 4.7 | H6: On Track
A7: 1 | B7: Jan-2024 | C7: Warehouse Operations | D7: 96800 | E7: 90560 | F7: -6240 | G7: -6.4 | H7: Under Budget
A8: 1 | B8: Jan-2024 | C8: Office & Admin | D8: 48400 | E8: 50147 | F8: 1747 | G8: 3.6 | H8: On Track
A9: 1 | B9: Jan-2024 | C9: Communication & IT | D9: 35200 | E9: 34471 | F9: -729 | G9: -2.1 | H9: On Track
A10: 1 | B10: Jan-2024 | C10: Insurance & Compliance | D10: 66000 | E10: 66034 | F10: 34 | G10: 0.1 | H10: On Track
A11: 1 | B11: Jan-2024 | C11: Miscellaneous | D11: 26400 | E11: 25283 | F11: -1117 | G11: -4.2 | H11: On Track
A12: 2 | B12: Feb-2024 | C12: Salaries & Wages | D12: 546000 | E12: 539738 | F12: -6262 | G12: -1.1 | H12: On Track
A13: 2 | B13: Feb-2024 | C13: Vehicle Fuel & Maintenance | D13: 235200 | E13: 234981 | F13: -219 | G13: -0.1 | H13: On Track
... A121: 12 | B121: Dec-2024 | C121: Miscellaneous | D121: 31500 | E121: 35490 | F121: 3990 | G121: 12.7 | H121: Over Budget

Sheet 👤 Rep Performance
A1: SALES REP PERFORMANCE SCORECARD — FY 2024
A2: Individual Performance vs Target | All Regions | FY 2024
B4: 👥 TOTAL REPS | C4: 📦 TOTAL SALES | D4: 🏆 AVG ACHIEVEMENT % | E4: 🥇 TOP REP | F4: 🔴 REPS BELOW 90% | G4: ✅ REPS ON TARGET | H4: 💰 TOTAL GROSS PROFIT | I4: 📋 TOTAL INVOICES
B5: =COUNTA(DATA_REP!B2:B9) -> 8 | C5: =SUM(DATA_REP!D2:D9) -> 57579897 | D5: =IFERROR(AVERAGE(DATA_REP!I2:I9),0) -> 409.3625 | E5: =INDEX(DATA_REP!B2:B9,MATCH(MAX(DATA_REP!D2:D9),DATA_REP!D2:D9,0)) -> Ravi Deshmukh | F5: =COUNTIF(DATA_REP!I2:I9,"<90") -> 0 | G5: =COUNTIF(DATA_REP!I2:I9,">=95") -> 8 | H5: =SUM(DATA_REP!F2:F9) -> 19942238 | I5: =SUM(DATA_REP!G2:G9) -> 9420
A7: # | B7: Rep Name | C7: Region | D7: Net Sales (₹) | E7: Annual Target (₹) | F7: Achievement % | G7: Units Sold | H7: Gross Profit (₹) | I7: Invoices | J7: Rank
A8: 1 | B8: =DATA_REP!B2 -> Ravi Deshmukh | C8: =DATA_REP!C2 -> Nagpur East | D8: =DATA_REP!D2 -> 8655178.2 | E8: =DATA_REP!H2 -> 2100000 | F8: =IFERROR(D8/E8*100,0) -> 412.15134 | G8: =DATA_REP!E2 -> 104827 | H8: =DATA_REP!F2 -> 2999742.4 | I8: =DATA_REP!G2 -> 1408 | J8: =RANK(D8,D$8:D$15,0) -> 1
A9: 2 | B9: =DATA_REP!B3 -> Sanjay Bhagat | C9: =DATA_REP!C3 -> Nagpur West | D9: =DATA_REP!D3 -> 8187190 | E9: =DATA_REP!H3 -> 1980000 | F9: =IFERROR(D9/E9*100,0) -> 413.49444 | G9: =DATA_REP!E3 -> 100636 | H9: =DATA_REP!F3 -> 2837486.4 | I9: =DATA_REP!G3 -> 1332 | J9: =RANK(D9,D$8:D$15,0) -> 2
A10: 3 | B10: =DATA_REP!B4 -> Amit Tiwari | C10: =DATA_REP!C4 -> Nagpur Central | D10: =DATA_REP!D4 -> 7904062.9 | E10: =DATA_REP!H4 -> 2160000 | F10: =IFERROR(D10/E10*100,0) -> 365.92884 | G10: =DATA_REP!E4 -> 98406 | H10: =DATA_REP!F4 -> 2738800.3 | I10: =DATA_REP!G4 -> 1306 | J10: =RANK(D10,D$8:D$15,0) -> 3
A11: 4 | B11: =DATA_REP!B5 -> Nitin Wankhede | C11: =DATA_REP!C5 -> Amravati | D11: =DATA_REP!D5 -> 6826375.3 | E11: =DATA_REP!H5 -> 1740000 | F11: =IFERROR(D11/E11*100,0) -> 392.32042 | G11: =DATA_REP!E5 -> 87924 | H11: =DATA_REP!F5 -> 2363193.9 | I11: =DATA_REP!G5 -> 1139 | J11: =RANK(D11,D$8:D$15,0) -> 4
A12: 5 | B12: =DATA_REP!B6 -> Rahul Chaudhary | C12: =DATA_REP!C6 -> Buldhana | D12: =DATA_REP!D6 -> 6755123.3 | E12: =DATA_REP!H6 -> 1440000 | F12: =IFERROR(D12/E12*100,0) -> 469.10579 | G12: =DATA_REP!E6 -> 83645 | H12: =DATA_REP!F6 -> 2338191.2 | I12: =DATA_REP!G6 -> 1079 | J12: =RANK(D12,D$8:D$15,0) -> 5
A13: 6 | B13: =DATA_REP!B7 -> Suresh Korde | C13: =DATA_REP!C7 -> Yavatmal | D13: =DATA_REP!D7 -> 6599432.7 | E13: =DATA_REP!H7 -> 1560000 | F13: =IFERROR(D13/E13*100,0) -> 423.04056 | G13: =DATA_REP!E7 -> 81172 | H13: =DATA_REP!F7 -> 2282386.7 | I13: =DATA_REP!G7 -> 1064 | J13: =RANK(D13,D$8:D$15,0) -> 6
A14: 7 | B14: =DATA_REP!B8 -> Mahesh Borkar | C14: =DATA_REP!C8 -> Akola | D14: =DATA_REP!D8 -> 6403643.2 | E14: =DATA_REP!H8 -> 1500000 | F14: =IFERROR(D14/E14*100,0) -> 426.90954 | G14: =DATA_REP!E8 -> 79211 | H14: =DATA_REP!F8 -> 2218927.7 | I14: =DATA_REP!G8 -> 1060 | J14: =RANK(D14,D$8:D$15,0) -> 7
A15: 8 | B15: =DATA_REP!B9 -> Deepak Pande | C15: =DATA_REP!C9 -> Wardha | D15: =DATA_REP!D9 -> 6248891.2 | E15: =DATA_REP!H9 -> 1680000 | F15: =IFERROR(D15/E15*100,0) -> 371.95781 | G15: =DATA_REP!E9 -> 74814 | H15: =DATA_REP!F9 -> 2163509 | I15: =DATA_REP!G9 -> 1032 | J15: =RANK(D15,D$8:D$15,0) -> 8
B16: TEAM TOTAL | D16: =SUM(D8:D15) -> 57579897 | E16: =SUM(E8:E15) -> 14160000 | F16: =IFERROR(D16/E16*100,0) -> 406.63769 | G16: =SUM(G8:G15) -> 710635 | H16: =SUM(H8:H15) -> 19942238 | I16: =SUM(I8:I15) -> 9420

Sheet DATA_REP
A1: rep_id | B1: rep_name | C1: region | D1: Total_Net_Sales | E1: Total_Units | F1: Total_Gross_Profit | G1: Total_Invoices | H1: Annual_Target | I1: Achievement_%
A2: SR02 | B2: Ravi Deshmukh | C2: Nagpur East | D2: 8655178.2 | E2: 104827 | F2: 2999742.4 | G2: 1408 | H2: 2100000 | I2: 412.2
A3: SR03 | B3: Sanjay Bhagat | C3: Nagpur West | D3: 8187190 | E3: 100636 | F3: 2837486.4 | G3: 1332 | H3: 1980000 | I3: 413.5
A4: SR01 | B4: Amit Tiwari | C4: Nagpur Central | D4: 7904062.9 | E4: 98406 | F4: 2738800.3 | G4: 1306 | H4: 2160000 | I4: 365.9
A5: SR07 | B5: Nitin Wankhede | C5: Amravati | D5: 6826375.3 | E5: 87924 | F5: 2363193.9 | G5: 1139 | H5: 1740000 | I5: 392.3
A6: SR10 | B6: Rahul Chaudhary | C6: Buldhana | D6: 6755123.3 | E6: 83645 | F6: 2338191.2 | G6: 1079 | H6: 1440000 | I6: 469.1
A7: SR06 | B7: Suresh Korde | C7: Yavatmal | D7: 6599432.7 | E7: 81172 | F7: 2282386.7 | G7: 1064 | H7: 1560000 | I7: 423
A8: SR09 | B8: Mahesh Borkar | C8: Akola | D8: 6403643.2 | E8: 79211 | F8: 2218927.7 | G8: 1060 | H8: 1500000 | I8: 426.9
A9: SR05 | B9: Deepak Pande | C9: Wardha | D9: 6248891.2 | E9: 74814 | F9: 2163509 | G9: 1032 | H9: 1680000 | I9: 372

Sheet 📋 Weekly Summary
A1: SHREENATH AGRO & FMCG DISTRIBUTORS PVT. LTD.
A2: WEEKLY MIS SUMMARY — AUTO-GENERATED MANAGEMENT REPORT | FY 2024
A4: 📊 SECTION 1 — SALES PERFORMANCE
B5: YTD Net Sales | C5: ='📊 Sales MIS'!C20 -> 58547393 | D5: Sum of all 12 months
B6: YTD Sales Target | C6: ='📊 Sales MIS'!D20 -> 63071496 | D6: Sum of all monthly targets
B7: YTD Achievement % | C7: ='📊 Sales MIS'!E20 -> 92.827024 | D7: Actual / Target × 100
B8: YTD Gross Profit | C8: ='📊 Sales MIS'!F20 -> 19942239 | D8: Revenue minus COGS
B9: YTD GP Margin % | C9: ='📊 Sales MIS'!G20 -> 34.061703 | D9: Gross Profit / Net Sales × 100
B10: Best Sales Month | C10: =INDEX('📊 Sales MIS'!B8:B19,MATCH(MAX('📊 Sales MIS'!C8:C19),'📊 Sales MIS'!C8:C19,0)) -> Nov-2024 | D10: Month with highest net sales
B11: Highest Monthly Sales | C11: =MAX('📊 Sales MIS'!C8:C19) -> 5872524 | D11: Peak month revenue
B12: Lowest Monthly Sales | C12: =MIN('📊 Sales MIS'!C8:C19) -> 3961742 | D12: Lowest month revenue
B13: Sales Exception Flag | C13: =IF('📊 Sales MIS'!E20<80,"🔴 ALERT: Below 80% of Target",IF('📊 Sales MIS'!E20<95,"🟡 WARNING: Below 95%","✅ ON TRACK")) -> 🟡 WARNING: Below 95% | D13: Auto-generated alert
A15: 📦 SECTION 2 — INVENTORY & OPERATIONS
B16: Total GRN Units | C16: ='📦 Inventory Report'!C20 -> 18.9 | D16: Total goods received
B17: Total Issued Units | C17: ='📦 Inventory Report'!D20 -> 3001438 | D17: Total dispatched to market
B18: Total Damage Units | C18: ='📦 Inventory Report'!E20 -> 2895608 | D18: Damaged / expired units
B19: Damage Rate % | C19: =IFERROR('📦 Inventory Report'!H5,0) -> 15320677 | D19: Damage / GRN × 100
B20: Total Dispatch Trips | C20: ='📦 Inventory Report'!B5 -> 18.9 | D20: All depot trips FY 2024
B21: On-Time Deliveries | C21: ='📦 Inventory Report'!C5 -> 3001438 | D21: Trips delivered on time
B22: Average OTD % | C22: ='📦 Inventory Report'!G5 -> 97.833333 | D22: On-Time Delivery rate
B23: OTD Exception Flag | C23: =IF('📦 Inventory Report'!D5<85,"🔴 ALERT: OTD Below 85%",IF('📦 Inventory Report'!D5<90,"🟡 WARNING: OTD Below 90%","✅ OTD ON TRACK")) -> ✅ OTD ON TRACK | D23: Auto-generated alert
A25: 💰 SECTION 3 — COST & PROFITABILITY
B26: Total Actual OpEx | C26: ='💰 Cost Variance'!C5 -> 20012400 | D26: All operating expenses FY 2024
B27: Total OpEx Budget | C27: ='💰 Cost Variance'!D5 -> 311912 | D27: Annual budget
B28: OpEx Variance (₹) | C28: ='💰 Cost Variance'!E5 -> 6316.0404 | D28: Actual minus Budget
B29: OpEx Variance % | C29: ='💰 Cost Variance'!F5 -> 25 | D29: Variance / Budget × 100
B30: Months Over Budget | C30: ='💰 Cost Variance'!G5 -> 13 | D30: Count of over-budget months
B31: Months Under Budget | C31: ='💰 Cost Variance'!H5 -> 🔴 Over Budget | D31: Count of under-budget months
B32: Cost Exception Flag | C32: ='💰 Cost Variance'!I5 -> 🔴 Over Budget | D32: Auto-generated alert
A34: 👤 SECTION 4 — SALES REP HIGHLIGHTS
B35: Top Performing Rep | C35: =INDEX('👤 Rep Performance'!B8:B17,MATCH(MAX('👤 Rep Performance'!D8:D17),'👤 Rep Performance'!D8:D17,0)) -> TEAM TOTAL | D35: Highest net sales
B36: Top Rep Net Sales | C36: =MAX('👤 Rep Performance'!D8:D17) -> 57579897
B37: Team Avg Achievement % | C37: ='👤 Rep Performance'!D5 -> 409.3625 | D37: Full team average
B38: Reps Below 90% Target | C38: ='👤 Rep Performance'!F5 -> 0 | D38: Needs attention
B39: Reps At/Above 95% Target | C39: =COUNTIF('👤 Rep Performance'!F8:F17,">="&95) -> 9 | D39: On track
A41: 🚨 SECTION 5 — EXCEPTION ALERTS DASHBOARD
B42: Sales Achievement Alert | C42: =IF('📊 Sales MIS'!E20<80,"🔴 CRITICAL: Sales <80%",IF('📊 Sales MIS'!E20<95,"🟡 WARNING: Sales <95%","✅ Sales OK")) -> 🟡 WARNING: Sales <95%
B43: OTD Performance Alert | C43: =IF('📦 Inventory Report'!D5<85,"🔴 CRITICAL: OTD <85%",IF('📦 Inventory Report'!D5<90,"🟡 WARNING: OTD <90%","✅ OTD OK")) -> ✅ OTD OK
B44: OpEx Budget Alert | C44: =IF('💰 Cost Variance'!F5>10,"🔴 CRITICAL: OpEx >10% over",IF('💰 Cost Variance'!F5>5,"🟡 WARNING: OpEx >5% over","✅ Cost OK")) -> 🔴 CRITICAL: OpEx >10% over
B45: Damage Rate Alert | C45: =IF('📦 Inventory Report'!G20>2,"🔴 CRITICAL: Damage Rate >2%",IF('📦 Inventory Report'!G20>1,"🟡 WARNING: Damage Rate >1%","✅ Damage OK")) -> 🔴 CRITICAL: Damage Rate >2%
...
